<?xml version="1.0"?>
<robot name="myrobot" xmlns:xacro="http://www.ros.org/wiki/xacro">
  <material name="white">
    <color rgba="0.87 0.90 0.87 1.0"/>
  </material>
  <material name="black">
    <color rgba="0.0 0.0 0.0 1.0"/>
  </material>
  <material name="green">
    <color rgba="0.22 0.32 0.14 1.0"/>
  </material>
  <material name="Green">
    <color rgba="0.0 0.8 0.0 1.0"/>
  </material>
  <material name="OffWhite">
    <color rgba="0.8 0.8 0.8 1"/>
  </material>
  <material name="yellow">
     <color rgba="1 1 0 1"/>
  </material>

  <link name="base_link">
     <visual>
       <geometry>
          <!--<cylinder length="0.0042" radius="0.2" />-->
          <mesh filename="package://myrobot/meshes/ROS.stl" scale="0.001016 0.001016 0.001016"/>
       </geometry>
       <material name="blue">
         <color rgba="0 0 0.8 1" />
       </material>
       <origin rpy="0 0 -1.57075" xyz="0 0 0.04 " />
     </visual>
  </link>
<!--This is added to the last 4 supports-->
  <link name="right_wheel">
     <visual>
       <geometry>
          <cylinder length="0.06" radius="0.06" />
       </geometry>
       <origin xyz="0 0 0.04 " />
       <material name="black"/>
     </visual>
  </link>

   <joint name="right_wheel_joint" type="continuous">
      <parent link="base_link" />
      <child  link="right_wheel" />
       <axis xyz="0 0 1" />
      <origin rpy="0 1.57075 1.57075" xyz="-0.075 -0.19 0.06" />
      <!--<origin rpy="0 1.57057 0" xyz="0.19 0.075 0.02" />-->
   </joint>

   <link name="right_wheel_axis">
      <visual>
        <geometry>
           <cylinder length="0.06" radius="0.01" />
        </geometry>
        <origin xyz="0 0 0.04 " />
        <material name="Green" />
      </visual>
   </link>

   <joint name="right_wheel_axis_joint" type="fixed">
      <parent link="base_link" />
      <child  link="right_wheel_axis" />
      <origin rpy="0 1.57075 1.57075" xyz="-0.075 -0.13 0.06" />
      <!--<origin rpy="0 1.57057 0" xyz="0.13 0.075 0.02" />-->
   </joint>

  <link name="left_wheel">
     <visual>
       <geometry>
          <cylinder length="0.06" radius="0.06" />
       </geometry>
        <!--<origin rpy="0 -1.57057 0" xyz="-0.19 0.075 0" />-->
        <origin xyz="0 0 0.04 " />
       <material name="black" />
     </visual>
  </link>

  <joint name="left_wheel_joint" type="continuous">
      <parent link="base_link" />
      <child  link="left_wheel" />
      <axis xyz="0 0 1" />
      <!--<origin rpy="0 -1.57057 0" xyz="-0.19 0.075 0.02" />-->
      <origin rpy="0 -1.57075 1.57075" xyz="-0.075 0.19 0.06" />
  </joint>

  <link name="left_wheel_axis">
      <visual>
        <geometry>
           <cylinder length="0.06" radius="0.01" />
        </geometry>
        <origin xyz="0 0 0.035" />
        <material name="Green" />
      </visual>
  </link>

  <joint name="left_wheel_axis_joint" type="fixed">
      <parent link="base_link" />
      <child  link="left_wheel_axis" />
      <!--<origin rpy="0 -1.57057 0" xyz="-0.13 0.075 0.02" />-->
      <origin rpy="0 -1.57075 1.57075" xyz="-0.075 0.13 0.055" />
  </joint>
<!--End-->

<!--This is added to the last 4 supports-->

  <link name="left_brace_front">
    <visual>
       <geometry>
          <cylinder length="0.32" radius="0.004" />
       </geometry>
       <material name="green">
          <color rgba=".86 .86 .86 1" />
       </material>
    </visual>
  </link>

  <joint name="left_brace_front_joint" type="fixed">
     <parent link="base_link" />
     <child  link="left_brace_front"/>
     <origin xyz="0.1 0.1 0.2" />
  </joint>

  <link name="left_brace_back">
    <visual>
       <geometry>
          <cylinder length="0.32" radius="0.004" />
       </geometry>
       <material name="green">
          <color rgba="0.86 0.86 0.86 1" />
       </material>
    </visual>
  </link>

  <joint name="left_brace_back_joint" type="fixed">
     <parent link="base_link" />
     <child  link="left_brace_back"/>
     <origin xyz="0.1 -0.1 0.2" />
  </joint>

  <link name="right_brace_front">
    <visual>
       <geometry>
          <cylinder length="0.32" radius="0.004" />
       </geometry>
       <material name="green">
          <color rgba=".86 .86 .86 1" />
       </material>
    </visual>
  </link>

  <joint name="right_brace_front_joint" type="fixed">
     <parent link="base_link" />
     <child  link="right_brace_front"/>
     <origin xyz="-0.1 0.1 0.2" />
  </joint>

  <link name="right_brace_back">
    <visual>
       <geometry>
          <cylinder length="0.32" radius="0.004" />
       </geometry>
       <material name="green">
          <color rgba=".86 .86 .86 1" />
       </material>
    </visual>
  </link>

  <joint name="right_brace_back_joint" type="fixed">
     <parent link="base_link" />
     <child  link="right_brace_back"/>
     <origin xyz="-0.1 -0.1 0.2" />
  </joint>
<!--End-->

<!--This is the rplidar-->
    <link name="rplidar">
       <visual>
         <geometry>
            <cylinder length="0.046" radius="0.035"/> 
         </geometry>
         <origin xyz="0 0 0.04" />
         <material name="OffWhite" />
       </visual>
    </link>

    <joint name="rplidar_joint" type="fixed">
       <parent link="rplidar_bottom" />
       <child  link="rplidar"/>
       <!--<origin xyz="0 0.012 0.033" />-->
       <origin rpy="0 0 1.57075" xyz="0 0.012 0.033" />
    </joint>

    <link name="rplidar_bottom">
      <visual>
         <geometry>
            <box size="0.07 0.096 0.033" />
         </geometry>
         <origin xyz="0 0 0.04" />
         <material name="yellow" />
      </visual>
    </link>
  
    <joint name="rplidar_bottom_joint" type="fixed">
       <parent link="base_link" />
       <child  link="rplidar_bottom" />
       <!--<origin  xyz="0 0.104 0.34" />-->
       <origin rpy="0 0 1.57075" xyz="-0.104 0 0.34" />
    </joint>
<!--End-->

</robot>
